Workbook
Name Buyers: DropDownLists!$A$202:$A$225
Name DepartmentList: DropDownLists!$A$3:$A$60
Name LocationList: DropDownLists!$C$202:$C$220
Name WarehouseAddresses: WarehouseTable[Address]

Sheet Purchase Order
A1: BUYER: | B1: Drew Chase | F1: ROUTING: | G1: traffic@mardens.com | I1: INVOICES | J1: ap@mardens.com | M1: #VALUE!
A2: PO #: | B2: 123456789 | F2: SHIP TO: | G2: 100 Benton Ave, Winslow, ME 04901 | I2: SHIP FROM: | J2: 123 Main Street, Small Town, USA
A3: VENDOR: | B3: Walmart | F3: TERMS: | G3: A Firm Handshake | I3: NOTES: | J3: His handshake was wet.
A5: ITEM # | B5: UPC | C5: DESCRIPTION | D5: CASE PACK | E5: CASES | F5: QTY | G5: MARDENS COST | H5: MARDENS PRICE | I5: COMP RETAIL | J5: DEPARTMENT | K5: CATEGORY | L5: SUB CATEGORY | M5: SEASON/ Holiday | N5: BUYER NOTES
A6: 1000001 | B6: 4965802 | C6: Diet Coke (16 Oz Can) | D6: 1 | E6: 1 | F6: 1 | G6: 0.2 | H6: 0.56 | I6: 1.2 | J6: Consumables - CON | K6: Food - FOOD | L6: Grocery - GROC | N6: Something that I just had on my desk
A7: 1000002 | B7: 4965803 | C7: Diet Coke (16 Oz Can) | D7: 1 | E7: 1 | F7: 1 | G7: 0.2 | H7: 0.56 | I7: 1.2 | J7: Consumables - CON | K7: Food - FOOD | L7: Grocery - GROC | N7: Something that I just had on my desk
A8: 1000003 | B8: 4965804 | C8: Diet Coke (16 Oz Can) | D8: 1 | E8: 1 | F8: 1 | G8: 0.2 | H8: 0.56 | I8: 1.2 | J8: Consumables - CON | K8: Food - FOOD | L8: Grocery - GROC | N8: Something that I just had on my desk
A9: 1000004 | B9: 4965805 | C9: Diet Coke (16 Oz Can) | D9: 1 | E9: 1 | F9: 1 | G9: 0.2 | H9: 0.56 | I9: 1.2 | J9: Consumables - CON | K9: Food - FOOD | L9: Grocery - GROC | N9: Something that I just had on my desk
A10: 1000005 | B10: 4965806 | C10: Diet Coke (16 Oz Can) | D10: 1 | E10: 1 | F10: 1 | G10: 0.2 | H10: 0.56 | I10: 1.2 | J10: Consumables - CON | K10: Food - FOOD | L10: Grocery - GROC | N10: Something that I just had on my desk
A11: 1000006 | B11: 4965807 | C11: Diet Coke (16 Oz Can) | D11: 1 | E11: 1 | F11: 1 | G11: 0.2 | H11: 0.56 | I11: 1.2 | J11: Consumables - CON | K11: Food - FOOD | L11: Grocery - GROC | N11: Something that I just had on my desk
A12: 1000007 | B12: 4965808 | C12: Diet Coke (16 Oz Can) | D12: 1 | E12: 1 | F12: 1 | G12: 0.2 | H12: 0.56 | I12: 1.2 | J12: Consumables - CON | K12: Food - FOOD | L12: Grocery - GROC | N12: Something that I just had on my desk
A13: 1000008 | B13: 4965809 | C13: Diet Coke (16 Oz Can) | D13: 1 | E13: 1 | F13: 1 | G13: 0.2 | H13: 0.56 | I13: 1.2 | J13: Consumables - CON | K13: Food - FOOD | L13: Grocery - GROC | N13: Something that I just had on my desk
A14: 1000009 | B14: 4965810 | C14: Diet Coke (16 Oz Can) | D14: 1 | E14: 1 | F14: 1 | G14: 0.2 | H14: 0.56 | I14: 1.2 | J14: Consumables - CON | K14: Food - FOOD | L14: Grocery - GROC | N14: Something that I just had on my desk
A15: 1000010 | B15: 4965811 | C15: Diet Coke (16 Oz Can) | D15: 1 | E15: 1 | F15: 1 | G15: 0.2 | H15: 0.56 | I15: 1.2 | J15: Consumables - CON | K15: Food - FOOD | L15: Grocery - GROC | N15: Something that I just had on my desk
A16: 1000011 | B16: 4965812 | C16: Diet Coke (16 Oz Can) | D16: 1 | E16: 1 | F16: 1 | G16: 0.2 | H16: 0.56 | I16: 1.2 | J16: Consumables - CON | K16: Food - FOOD | L16: Grocery - GROC | N16: Something that I just had on my desk
A17: 1000012 | B17: 4965813 | C17: Diet Coke (16 Oz Can) | D17: 1 | E17: 1 | F17: 1 | G17: 0.2 | H17: 0.56 | I17: 1.2 | J17: Consumables - CON | K17: Food - FOOD | L17: Grocery - GROC | N17: Something that I just had on my desk
... A34: 1000029 | B34: 4965830 | C34: Diet Coke (16 Oz Can) | D34: 1 | E34: 1 | F34: 1 | G34: 0.2 | H34: 0.56 | I34: 1.2 | J34: Consumables - CON | K34: Food - FOOD | L34: Grocery - GROC | N34: Something that I just had on my desk
F35: =D35*E35 -> 0
F36: =D36*E36 -> 0
F37: =D37*E37 -> 0
F38: =D38*E38 -> 0
F39: =D39*E39 -> 0
F40: =D40*E40 -> 0
F41: =D41*E41 -> 0
F42: =D42*E42 -> 0
F43: =D43*E43 -> 0
F44: =D44*E44 -> 0
F45: =D45*E45 -> 0
F46: =D46*E46 -> 0
... F199: =D199*E199 -> 0

Sheet Categories Breakdown
A1: Dept (ACCT CODE) | B1: Categories | C1: Sub-categories | D1: Notes | F1: Season | G1: Short Name | H1: Code | J1: Status | K1: Description | M1: Buyer | N1: Name | P1: Warehouse | Q1: Location | R1: Address
A2: Clothing - CLO | B2: Baby - BABY | C2: Fall | F2: =G2 & " - " &H2 -> 4th Quarter - 4TH-Q | G2: 4th Quarter | H2: 4TH-Q | J2: AD | K2: Ad Item | M2: AM | N2: Andrew Marden | P2: WIN | Q2: Winslow | R2: 100 Benton Ave, Winslow, ME 04901
A3: Clothing - CLO | B3: Baby - BABY | C3: Marketing / Promo | F3: =G3 & " - " &H3 -> Christmas - CH | G3: Christmas | H3: CH | J3: ALL | K3: Split All | M3: BL | N3: Brandon Lowe | P3: LEW | Q3: Lewiston Mill | R3: 17 Locust Street, Lewiston, ME 04240
A4: Clothing - CLO | B4: Baby - BABY | C4: Spring | F4: =G4 & " - " &H4 -> Cinco De Mayo - CINCO | G4: Cinco De Mayo | H4: CINCO | J4: BAG | K4: Priced On Bag | M4: CW | N4: Charley Willey | P4: WTVL | Q4: Wtvl - 50 Industrial | R4: 50 Industrial Dr, Waterville, ME 04901
A5: Clothing - CLO | B5: Baby - BABY | C5: Summer | F5: =G5 & " - " &H5 -> Father's Day - DAD | G5: Father's Day | H5: DAD | J5: DATED | K5: Dated Item!! | M5: EB | N5: Elizabeth Beuthiaume | P5: MULTI | Q5: Multiple Warehouses | R5: Various, see Buyer's Notes
A6: Clothing - CLO | B6: Baby - BABY | C6: Swim | F6: =G6 & " - " &H6 -> Easter - EA | G6: Easter | H6: EA | J6: HUNG | K6: Priced & Hung | M6: HAM | N6: Ham Marden
A7: Clothing - CLO | B7: Baby - BABY | C7: Winter | F7: =G7 & " - " &H7 -> Fall - FL | G7: Fall | H7: FL | J7: INPRO | K7: In Process | M7: JM | N7: Jake Marden
A8: Clothing - CLO | B8: Boys - BOYS | C8: Back to School | F8: =G8 & " - " &H8 -> Halloween - HAL | G8: Halloween | H8: HAL | J8: MADE | K8: Split Made | M8: JM1 | N8: John Marden
A9: Clothing - CLO | B9: Boys - BOYS | C9: Fall | F9: =G9 & " - " &H9 -> 4th of July - JULY4 | G9: 4th of July | H9: JULY4 | J9: QTR 1 | K9: 1st Quarter Split | M9: KC | N9: Ken Clark
A10: Clothing - CLO | B10: Boys - BOYS | C10: Marketing / Promo | F10: =G10 & " - " &H10 -> Mothers Day - MOM | G10: Mothers Day | H10: MOM | J10: QTR 2 | K10: 2nd Quarter Split | M10: JM2 | N10: Jon Martin
A11: Clothing - CLO | B11: Boys - BOYS | C11: Outerwear - JKT | F11: =G11 & " - " &H11 -> Back to School - SCHL | G11: Back to School | H11: SCHL | J11: QTR 3 | K11: 3rd Quarter Split | M11: SMS | N11: Sara Marden Slattery
A12: Clothing - CLO | B12: Boys - BOYS | C12: Outerwear - Pants | F12: =G12 & " - " &H12 -> Spring - SP | G12: Spring | H12: SP | J12: QTR 4 | K12: 4th Quarter Split
A13: Clothing - CLO | B13: Boys - BOYS | C13: Spring | F13: =G13 & " - " &H13 -> St Patricks Day - ST | G13: St Patricks Day | H13: ST | J13: SOME | K13: Split Part Of Stock
A14: Clothing - CLO | B14: Boys - BOYS | C14: Summer | F14: =G14 & " - " &H14 -> Summer - SU | G14: Summer | H14: SU | J14: SORT | K14: Sorted & Worked
A15: Clothing - CLO | B15: Boys - BOYS | C15: Sweatshirts / Sweatpants | F15: =G15 & " - " &H15 -> Thanksgiving - THANK | G15: Thanksgiving | H15: THANK | J15: STORE | K15: Store Ready
A16: Clothing - CLO | B16: Boys - BOYS | C16: Swim | F16: =G16 & " - " &H16 -> Transitional - TRAN | G16: Transitional | H16: TRAN
A17: Clothing - CLO | B17: Boys - BOYS | C17: Winter | F17: =G17 & " - " &H17 -> Valentines Day - VA | G17: Valentines Day | H17: VA
A18: Clothing - CLO | B18: Girls - GIRLS | C18: Back to School | F18: =G18 & " - " &H18 -> Winter - WI | G18: Winter | H18: WI
A19: Clothing - CLO | B19: Girls - GIRLS | C19: Fall
A20: Clothing - CLO | B20: Girls - GIRLS | C20: Marketing / Promo
A21: Clothing - CLO | B21: Girls - GIRLS | C21: Outerwear - JKT
A22: Clothing - CLO | B22: Girls - GIRLS | C22: Outerwear - Pants
A23: Clothing - CLO | B23: Girls - GIRLS | C23: Spring
A24: Clothing - CLO | B24: Girls - GIRLS | C24: Summer
A25: Clothing - CLO | B25: Girls - GIRLS | C25: Sweatshirts / Sweatpants
A26: Clothing - CLO | B26: Girls - GIRLS | C26: Swim
A27: Clothing - CLO | B27: Girls - GIRLS | C27: Winter
A28: Clothing - CLO | B28: Hunting
A29: Clothing - CLO | B29: Maine Sweatshirts | C29: Adult
A30: Clothing - CLO | B30: Maine Sweatshirts | C30: Kids
A31: Clothing - CLO | B31: Mens - MENS | C31: Fall
A32: Clothing - CLO | B32: Mens - MENS | C32: Jean's
A33: Clothing - CLO | B33: Mens - MENS | C33: Marketing / Promo
A34: Clothing - CLO | B34: Mens - MENS | C34: Outerwear - JKT
A35: Clothing - CLO | B35: Mens - MENS | C35: Outerwear - Pants
A36: Clothing - CLO | B36: Mens - MENS | C36: Spring
A37: Clothing - CLO | B37: Mens - MENS | C37: Summer
A38: Clothing - CLO | B38: Mens - MENS | C38: Sweatshirts / Sweatpants
A39: Clothing - CLO | B39: Mens - MENS | C39: Swim
A40: Clothing - CLO | B40: Mens - MENS | C40: Winter
...

Sheet Furniture Flooring Buyer notes
A1: KEN/FLOORING | F1: Major Furniture Categories
A2: Hardwood | F2: • Living Room Furniture
A3: Finished | F3: Sofas,
A4: Unfinished | F4: sectionals,
F5: loveseats
A6: Vinyl Plank | F6: Recliners,
A7: Click | F7: armchairs
A8: Glue Down | F8: • Coffee tables, end tables
A9: Floating | F9: • TV stands, entertainment centers
F10: • Bookcases, shelving units
A11: Laminate Plank | F11: • Bedroom Furniture
F12: Beds (twin, queen, king)
A13: Hybrid Plank | F13: Dressers, chests of drawers
F14: Nightstands
A15: Tile | F15: Wardrobes/armoires
A16: Ceramic
A17: Porcelain | F17: • Dining Room Furniture
F18: Dining tables
A19: Carpet Tile | F19: Dining chairs
F20: Buffets,
A21: Rugs | F21: sideboards
A22: Bound Rugs | F22: Bar carts, wine racks
A23: Scatter Rugs | F23: Counter-height tables & stools
A24: Runners
A25: Rolled Runners | F25: • Office Furniture
A26: Area Rugs | F26: Desks
A27: Patio Rugs | F27: Office chairs
F28: Filing cabinets
A29: Stair Treads | F29: Bookcases
F30: Conference tables
A31: Mats | F31: • Outdoor Furniture
A32: Interior | F32: Patio sets (tables & chairs)
A33: Exterior | F33: Lounge chairs
F34: Outdoor sofas & sectionals
A35: Carpet | F35: Umbrellas & gazebos
A36: Rolls | F36: Storage benches
A37: Rems
A38: Vinyl | F38: Accent & Specialty Categories
A39: Rolls | F39: Accent Furniture
A40: Rems | F40: Console tables
...

Sheet Cheat Sheet for Buyers
A1: Action | B1: Short Cut | C1: Example
A2: Autofill info | B2: CTRL + D | C2: fill department on entire sheet once you have it put in cell J7
A3: Copy | B3: CTRL + C
A4: Paste | B4: CTRL + V
A5: highlight column or row until next break | B5: CTRL + SHIFT + ARROW
A6: add filters | B6: Highlight row 5; CRTL + SHIFT + L | C6: filter for price, cost, type of item (ex candles) to easily add info using autofill

Sheet DropDownLists
A1: DepartmentList | B1: CategoriesList | C1: Categories | Y1: SubCategoriesList
A2: Department | B2: Categories | C2: {=TRANSPOSE(_xlfn._xlws.SORT(_xlfn.UNIQUE(DeptCatSubTable[Dept (ACCT CODE)])))} -> Clothing - CLO | D2: Consumables - CON | E2: Domestics - DOM | F2: Fabric - FAB | G2: Flooring | H2: Furniture | I2: General - GEN | J2: Hardware - HDW | K2: Housewares - HSW | L2: Pets - PETS | M2: SALVAGE | N2: Shoes - SHO | O2: Socks - SOCKS | P2: Softlines Acc - ACC | Q2: Sporting Goods - SPO | R2: Store Use - STR | Y2: {=TRANSPOSE(_xlfn._xlws.SORT(_xlfn.UNIQUE(DeptCatSubTable[Categories])))} -> Accent Chairs | Z2: Accent Furniture | AA2: Adhesive | AB2: Art Supplies - ART | AC2: Automotive - AUTO | AD2: Baby | AE2: Baby - BABY | AF2: Bakeware - BKW | AG2: Baseball - BASE | AH2: Basketball - BBALL | AI2: Batteries - BATT | AJ2: BBQ Items - BBQ | AK2: Bed Bases & Frames | AL2: Bedding & Accessories | AM2: Bedroom Furniture | AN2: Blankets - BLANK | AO2: Boating - BOAT | AP2: Books - BOOKS | AQ2: Bows | AR2: Boys - BOYS | AS2: Boys Acc - BOYS | AT2: Boys Socks - BOYS | AU2: Camping - CAMP | AV2: Candles - CAND | AW2: Carpet | AX2: Carpet Cores | AY2: Carpet Tile | AZ2: Children's Furniture | BA2: Cleaning Supplies - CLEAN | BB2: Clothing - CLO | BC2: Collars/Leashes - LEASH | BD2: Comforters - COMF | BE2: Console Tables | BF2: Consumables - CON | BG2: Cookware - CKW | BH2: Curtains/Drapes - CURT | BI2: Décor & Accessories | BJ2: Dining Room | BK2: Dinnerware - DINN | BL2: Domestics - DOM | BM2: Electronics - ELEC | BN2: Fabric - FAB | BO2: Fabric Yards - YARDS | BP2: FAK | BQ2: Fishing - FISH | BR2: Fitness - FITN | BS2: Flashlights - FLASH | BT2: Floor Cleaners - FLCLN | BU2: Food - FOOD | BV2: Football - FOOT | BW2: Frames - FRAME | BX2: Garden - GARD | BY2: General - GEN | BZ2: Gift Bags - BAGS | CA2: Gift Boxes - BOX | CB2: Gift Tags - TAGS | CC2: Girls - GIRLS | CD2: Girls Acc - GIRLS | CE2: Girls Socks - GIRLS | CF2: Glassware - GLASS | CG2: Golf - GOLF | CH2: Greeting Cards - CARDS | CI2: Hall Trees & Coat Racks | CJ2: Hand Tools - HAND | CK2: Hardware - HDW | CL2: Hardwood | CM2: HBC/HBA - HBC | CN2: Hockey - HOCK | CO2: Housewares - HSW | CP2: Hunting | CQ2: Hunting - HUNT | CR2: Hybrid Plank | CS2: Ice Fishing - ICE | CT2: Kids - SKIDS | CU2: Kitchen Gadgets - GADGE | CV2: Laminated Plank | CW2: Laundry - LAUN | CX2: Living Room | CY2: Luggage - LUGG | CZ2: Maine Sweatshirts | DA2: Mats | DB2: Mattresses | DC2: Mens - MENS | DD2: Mens - SMENS | DE2: Mens Acc - MENS | DF2: Mens Socks - MENS | DG2: Mixed gender | DH2: Monks Cloth | DI2: Notions - NOT | DJ2: Nuts & Bolts - NNB | DK2: Office Furniture | DL2: Office Supplies - OFFIC | DM2: Organization | DN2: Ottomans & Poufs | DO2: Outdoor Furniture | DP2: Outdoor- OUTDR | DQ2: Pad | DR2: Paint - PAINT | DS2: Paper Goods - PAPER | DT2: Party Goods - PARTY | DU2: Pet Beds - BEDS | DV2: Pet Food - PFOOD | DW2: Pet Toys - PTOYS | DX2: Pets - PETS | DY2: Pickleball- PKL | DZ2: Pillows - PILLW | EA2: Planters - PLANT | EB2: Plastics (Trash Bags, Ziploc Bags, etc.) - PLAST | EC2: Playground Balls - PGB | ED2: Power Tools - POWER | EE2: Rope - ROPE | EF2: Rugs | EG2: School Uniforms | EH2: Scrubs | EI2: Sheets - SHEET | EJ2: Shoes - SHO | EK2: Small Appliances - SMALL | EL2: Snow - SNOW | EM2: Soccer - SOCC | EN2: Socks - SOCKS | EO2: Softlines Acc - ACC | EP2: Sporting Goods - SPO | EQ2: Stair Treads | ER2: Storage Solutions | ES2: Store Use - STR | ET2: Tape - TAPE | EU2: Tarps - TARPS | EV2: Throw Rugs - RUGS | EW2: Tile | EX2: Tissue Paper - TISS | EY2: Towels - TOWEL | EZ2: Toys - TOYS | FA2: Treats/Chews - TREAT | FB2: Utility - UTIL | FC2: Vinyl | FD2: Vinyl Plank | FE2: Wall | FF2: Womens - SWMNS | FG2: Womens - WOMEN | FH2: Womens Acc - WOMEN | FI2: Womens Socks - WOMEN | FJ2: Work Gloves - GLOVE | FK2: Wrap | FL2: Yarn - YARN | FM2: 0
A3: {=_xlfn._xlws.SORT(_xlfn.UNIQUE(_xlfn.TOCOL(DeptCatSubTable[Dept (ACCT CODE)],1)))} -> Clothing - CLO | B3: {=_xlfn._xlws.SORT(_xlfn.UNIQUE(_xlfn.TOCOL(DeptCatSubTable[Categories],1)))} -> Accent Chairs | C3: {=_xlfn._xlws.SORT(_xlfn.UNIQUE(_xlfn._xlws.FILTER(DeptCatSubTable[Categories],DeptCatSubTable[Dept (ACCT CODE)]=DropDownLists!C2,"")))} -> Baby - BABY | D3: {=_xlfn._xlws.SORT(_xlfn.UNIQUE(_xlfn._xlws.FILTER(DeptCatSubTable[Categories],DeptCatSubTable[Dept (ACCT CODE)]=DropDownLists!D2,"")))} -> Cleaning Supplies - CLEAN | E3: {=_xlfn._xlws.SORT(_xlfn.UNIQUE(_xlfn._xlws.FILTER(DeptCatSubTable[Categories],DeptCatSubTable[Dept (ACCT CODE)]=DropDownLists!E2,"")))} -> Blankets - BLANK | F3: {=_xlfn._xlws.SORT(_xlfn.UNIQUE(_xlfn._xlws.FILTER(DeptCatSubTable[Categories],DeptCatSubTable[Dept (ACCT CODE)]=DropDownLists!F2,"")))} -> Fabric Yards - YARDS | G3: {=_xlfn._xlws.SORT(_xlfn.UNIQUE(_xlfn._xlws.FILTER(DeptCatSubTable[Categories],DeptCatSubTable[Dept (ACCT CODE)]=DropDownLists!G2,"")))} -> Adhesive | H3: {=_xlfn._xlws.SORT(_xlfn.UNIQUE(_xlfn._xlws.FILTER(DeptCatSubTable[Categories],DeptCatSubTable[Dept (ACCT CODE)]=DropDownLists!H2,"")))} -> Accent Chairs | I3: {=_xlfn._xlws.SORT(_xlfn.UNIQUE(_xlfn._xlws.FILTER(DeptCatSubTable[Categories],DeptCatSubTable[Dept (ACCT CODE)]=DropDownLists!I2,"")))} -> Art Supplies - ART | J3: {=_xlfn._xlws.SORT(_xlfn.UNIQUE(_xlfn._xlws.FILTER(DeptCatSubTable[Categories],DeptCatSubTable[Dept (ACCT CODE)]=DropDownLists!J2,"")))} -> Automotive - AUTO | ... X3: {=_xlfn._xlws.SORT(_xlfn.UNIQUE(_xlfn._xlws.FILTER(DeptCatSubTable[Categories],DeptCatSubTable[Dept (ACCT CODE)]=DropDownLists!X2,"")))} | Y3: {=_xlfn._xlws.SORT(_xlfn.UNIQUE(_xlfn._xlws.FILTER(DeptCatSubTable[Sub-categories],DeptCatSubTable[Categories]=DropDownLists!Y2,"")))} -> 0 | Z3: {=_xlfn._xlws.SORT(_xlfn.UNIQUE(_xlfn._xlws.FILTER(DeptCatSubTable[Sub-categories],DeptCatSubTable[Categories]=DropDownLists!Z2,"")))} -> 0 | AA3: {=_xlfn._xlws.SORT(_xlfn.UNIQUE(_xlfn._xlws.FILTER(DeptCatSubTable[Sub-categories],DeptCatSubTable[Categories]=DropDownLists!AA2,"")))} -> 0 | AB3: {=_xlfn._xlws.SORT(_xlfn.UNIQUE(_xlfn._xlws.FILTER(DeptCatSubTable[Sub-categories],DeptCatSubTable[Categories]=DropDownLists!AB2,"")))} -> Arts | AC3: {=_xlfn._xlws.SORT(_xlfn.UNIQUE(_xlfn._xlws.FILTER(DeptCatSubTable[Sub-categories],DeptCatSubTable[Categories]=DropDownLists!AC2,"")))} -> Brush/Scraper - WINTR | AD3: {=_xlfn._xlws.SORT(_xlfn.UNIQUE(_xlfn._xlws.FILTER(DeptCatSubTable[Sub-categories],DeptCatSubTable[Categories]=DropDownLists!AD2,"")))} -> 0 | AE3: {=_xlfn._xlws.SORT(_xlfn.UNIQUE(_xlfn._xlws.FILTER(DeptCatSubTable[Sub-categories],DeptCatSubTable[Categories]=DropDownLists!AE2,"")))} -> Fall | AF3: {=_xlfn._xlws.SORT(_xlfn.UNIQUE(_xlfn._xlws.FILTER(DeptCatSubTable[Sub-categories],DeptCatSubTable[Categories]=DropDownLists!AF2,"")))} -> 0 | ... FF3: {=_xlfn._xlws.SORT(_xlfn.UNIQUE(_xlfn._xlws.FILTER(DeptCatSubTable[Sub-categories],DeptCatSubTable[Categories]=DropDownLists!FF2,"")))} -> Boots - BOOTS
A4: Consumables - CON | B4: Accent Furniture | C4: Boys - BOYS | D4: Food - FOOD | E4: Comforters - COMF | F4: Monks Cloth | G4: Carpet | H4: Accent Furniture | I4: Baby | J4: Flashlights - FLASH | K4: Cookware - CKW | L4: Pet Beds - BEDS | M4: Consumables - CON | N4: Mens - SMENS | O4: Girls Socks - GIRLS | P4: Girls Acc - GIRLS | Q4: Basketball - BBALL | AB4: Crafts | AC4: Detailing - DTAIL | AE4: Marketing / Promo | AK4: Box Spring/Foundations | AL4: Cleaning Kits | AM4: Bed - Queen | AN4: Throw | AP4: Puzzle/Games | AR4: Fall | AS4: Belts | AT4: Fall | AU4: Tents/Shelters - TENT | AW4: Rolls | AZ4: Cribs & Toddler Beds | BI4: Lamps & Lighting | BJ4: Buffets | BO4: Fashion - FASHN | BU4: Canned Goods - CAN | BX4: Hand Tools - GTOOL | CC4: Fall | CD4: Belts | CE4: Fall | CL4: Unfinished | CT4: HASH | CX4: Bookcases/Shelving Units | CY4: Suitcase- SCSE | CZ4: Kids | DA4: Interior | DB4: Full/Double | DC4: Jean's | DD4: HASH | DE4: Belts | DF4: Fall | DG4: HASH | DJ4: Chain - CHAIN | DK4: Conference Tables | DM4: kitchen | DO4: Outdoor Sofas & Sectionals | DP4: Décor- LAWN | DQ4: Laminate Pad | DR4: Drop Cloths - DROP | DZ4: Decorative | EF4: Bound Rugs | EL4: Shovels - SHVLS | ER4: Shelving Units | ET4: Electrical Tape - ELECT | EU4: Heavy Duty - HEAVY | EW4: Porcelain | EY4: Beach - BEACH | EZ4: Indoor - INDR | FB4: Foam - FOAM | FC4: Rolls | FD4: Floating | FE4: Clock - CLOCK | FF4: HASH
A5: Domestics - DOM | B5: Adhesive | C5: Girls - GIRLS | D5: HBC/HBA - HBC | E5: Curtains/Drapes - CURT | F5: Notions - NOT | G5: Carpet Cores | H5: Bed Bases & Frames | I5: Batteries - BATT | J5: Garden - GARD | K5: Dinnerware - DINN | L5: Pet Food - PFOOD | M5: Domestics - DOM | N5: Mixed gender | O5: Mens Socks - MENS | P5: Mens Acc - MENS | Q5: Boating - BOAT | AC5: Floor Mats - MATS | AE5: Spring | AK5: Headboards & Footboards | AL5: Comforters & Duvets | AM5: Bed - Twin | AP5: Reading | AR5: Marketing / Promo | AS5: Caps | AT5: Spring | AZ5: Kids Desks & Chairs | BI5: Mirrors | BJ5: Counter-height Tables & Stools | BO5: Fleece - FLEECE | BU5: Grocery - GROC | BX5: Hose - HOSE | CC5: Marketing / Promo | CD5: Bras - BRA | CE5: Spring | CT5: Sandals - SNDAL | CX5: Coffee/End Tables | DB5: King | DC5: Marketing / Promo | DD5: Sandals - SNDAL | DE5: Caps | DF5: Spring | DG5: Sandals - SNDAL | DK5: Desks | DO5: Patio Sets (Tables & Chairs) | DP5: Pool Toys- POOL | DQ5: Non-skid Pad | DR5: Paint- PAINT | EF5: Patio Rugs | ER5: Shoe Racks | ET5: Masking Tape - MASK | EU5: Standard - STAND | EY5: Dish Towels - DISH | EZ5: Puzzles - PUZZ | FD5: Glue Down | FE5: Mirror - MIRR | FF5: Sandals - SNDAL
A6: Fabric - FAB | B6: Art Supplies - ART | C6: Hunting | D6: Laundry - LAUN | E6: Pillows - PILLW | F6: Utility - UTIL | G6: Carpet Tile | H6: Bedding & Accessories | I6: BBQ Items - BBQ | J6: Hand Tools - HAND | K6: Glassware - GLASS | L6: Pet Toys - PTOYS | M6: Fabric - FAB | N6: Womens - SWMNS | O6: Womens Socks - WOMEN | P6: Womens Acc - WOMEN | Q6: Fishing - FISH | AC6: Fluids - FLUID | AE6: Summer | AK6: Metal Frames | AL6: Mattress Bags/Covers (for moving/storage) | AM6: Dressers/Chest of Drawers | AR6: Outerwear - JKT | AS6: Mittens / Gloves | AT6: Summer | AZ6: Toy Storage | BI6: Rugs | BJ6: Dining Chairs | BO6: Home Décor - DÉCOR | BU6: Jarred Goods - JARS | BX6: Sprinklers, Nozzles - WATER | CC6: Outerwear - JKT | CD6: Caps | CE6: Summer | CT6: Shoe | CX6: Loveseats | DB6: Queen | DC6: Outerwear - JKT | DD6: Shoe | DE6: Mittens / Gloves | DF6: Summer | DG6: Shoe | DK6: Filing Cabinets | DO6: Storage Benches | DP6: Solar- SOLAR | DR6: Roller Covers - ROLLR | EF6: Rolled Runners | ER6: Storage Benches | ET6: Packing Tape - PACK | EY6: Hand - HAND | FF6: Shoe
A7: Flooring | B7: Automotive - AUTO | C7: Maine Sweatshirts | D7: Paper Goods - PAPER | E7: Sheets - SHEET | F7: Yarn - YARN | G7: Hardwood | H7: Bedroom Furniture | I7: Books - BOOKS | J7: Nuts & Bolts - NNB | K7: Kitchen Gadgets - GADGE | L7: Treats/Chews - TREAT | M7: FAK | Q7: Fitness - FITN | AC7: Jumper Cables - CABLE | AE7: Swim | AK7: Platform Beds | AL7: Mattress Protectors | AM7: Nightstands | AR7: Outerwear - Pants | AS7: Packaged Tees | AT7: Winter | BI7: Wall Art | BJ7: Dining Tables | BU7: Snack - SNACK | CC7: Outerwear - Pants | CD7: Mittens / Gloves | CE7: Winter | CT7: Slippers - SLIP | CX7: Recliners | DB7: Twin | DC7: Outerwear - Pants | DD7: Slippers - SLIP | DE7: Packaged Tees | DF7: Winter | DG7: Slippers - SLIP | DK7: Office Chairs | DO7: Umbrellas & Gazebos | DR7: Spray Paint - SPRAY | EF7: Runners | ET7: Painter's Tape - PAINT | EY7: Washcloths - WASH | FF7: Slippers - SLIP
A8: Furniture | B8: Baby | C8: Mens - MENS | E8: Throw Rugs - RUGS | G8: Hybrid Plank | H8: Children's Furniture | I8: Bows | J8: Paint - PAINT | K8: Organization | M8: General - GEN | Q8: Football - FOOT | AC8: Lubricants - LUBE | AE8: Winter | AL8: Mattress Toppers (Foam, Latex, Feather, Cooling Gel) | AM8: Wardrobes/Armoires | AR8: Spring | AS8: Purses | BJ8: Sideboards | CC8: Spring | CD8: Purses | CT8: Snow Boots | CX8: Sectionals | DB8: Twin XL | DC8: Spring | DD8: Snow Boots | DE8: Purses | DG8: Snow Boots | DR8: Stain - STAIN | EF8: Scatter Rugs | FF8: Snow Boots
A9: General - GEN | B9: Baby - BABY | C9: School Uniforms | E9: Towels - TOWEL | G9: Laminated Plank | H9: Console Tables | I9: Camping - CAMP | J9: Power Tools - POWER | K9: Small Appliances - SMALL | M9: Hardware - HDW | Q9: Golf - GOLF | AL9: Pillows (Memory foam, down, latex, cooling) | AR9: Summer | AS9: Underwear - UNDER | CC9: Summer | CD9: Underwear - UNDER | CT9: Transitional | CX9: Sofas | DC9: Summer | DD9: Transitional | DE9: Underwear - UNDER | DG9: Transitional | DR9: Tray Kits - KITS | FF9: Transitional
A10: Hardware - HDW | B10: Bakeware - BKW | C10: Scrubs | G10: Mats | H10: Décor & Accessories | I10: Candles - CAND | J10: Rope - ROPE | M10: Housewares - HSW | Q10: Hockey - HOCK | AL10: Sheets (Various sizes & materials) | AR10: Sweatshirts / Sweatpants | AS10: Winter Hats | CC10: Sweatshirts / Sweatpants | CD10: Winter Hats | CX10: TV Stands/Entertainment Center | DC10: Sweatshirts / Sweatpants | DE10: Winter Hats
A11: Housewares - HSW | B11: Baseball - BASE | C11: Womens - WOMEN | G11: Pad | H11: Dining Room | I11: Electronics - ELEC | J11: Snow - SNOW | M11: Pets - PETS | Q11: Hunting - HUNT | AL11: Under-bed Storage Solutions | AR11: Swim | CC11: Swim | DC11: Swim
A12: Pets - PETS | B12: Basketball - BBALL | G12: Rugs | H12: Hall Trees & Coat Racks | I12: Floor Cleaners - FLCLN | J12: Tape - TAPE | M12: Shoes - SHO | Q12: Ice Fishing - ICE | AR12: Winter | CC12: Winter | DC12: Winter
A13: SALVAGE | B13: Batteries - BATT | G13: Stair Treads | H13: Living Room | I13: Frames - FRAME | J13: Tarps - TARPS | M13: Socks - SOCKS | Q13: Pickleball- PKL
A14: Shoes - SHO | B14: BBQ Items - BBQ | G14: Tile | H14: Mattresses | I14: Gift Bags - BAGS | J14: Work Gloves - GLOVE | M14: Softlines Acc - ACC | Q14: Playground Balls - PGB
A15: Socks - SOCKS | B15: Bed Bases & Frames | G15: Vinyl | H15: Office Furniture | I15: Gift Boxes - BOX | M15: Sporting Goods - SPO | Q15: Soccer - SOCC
A16: Softlines Acc - ACC | B16: Bedding & Accessories | G16: Vinyl Plank | H16: Ottomans & Poufs | I16: Gift Tags - TAGS | M16: Store Use - STR
A17: Sporting Goods - SPO | B17: Bedroom Furniture | H17: Outdoor Furniture | I17: Greeting Cards - CARDS
A18: Store Use - STR | B18: Blankets - BLANK | H18: Storage Solutions | I18: Luggage - LUGG
B19: Boating - BOAT | I19: Office Supplies - OFFIC
B20: Books - BOOKS | I20: Outdoor- OUTDR
B21: Bows | I21: Party Goods - PARTY
B22: Boys - BOYS | I22: Planters - PLANT
B23: Boys Acc - BOYS | I23: Plastics (Trash Bags, Ziploc Bags, etc.) - PLAST
B24: Boys Socks - BOYS | I24: Tissue Paper - TISS
B25: Camping - CAMP | I25: Toys - TOYS
B26: Candles - CAND | I26: Wall
B27: Carpet | I27: Wrap
B28: Carpet Cores
B29: Carpet Tile
B30: Children's Furniture
B31: Cleaning Supplies - CLEAN
B32: Clothing - CLO
B33: Collars/Leashes - LEASH
B34: Comforters - COMF
B35: Console Tables
B36: Consumables - CON
B37: Cookware - CKW
B38: Curtains/Drapes - CURT
B39: Décor & Accessories
... B146: Yarn - YARN
...
